Workbook
Name DATEBISS: [1]!ALL_DATA[DATA_OSS]
Name NAN: [1]PARAMETRI!$A$36
Name SERIEBISS: [1]!ALL_DATA[#Headers]

Sheet 1AT
B2: Template corresponding to Part 1 of the project Fiscal Drag in Europe
B3: Yellow cells have to be filled by you (remember to rename the sheets as well)
B4: Remaing cells are automatically calculated using information from yellow cells (grey cells remain empty)
B8: Country | C8: AT | D8: Austria | E8: Updated: 21/01/2025
C10: Personal Income Tax Revenue | P10: Tac Base (il_fiscaldrag_all) | W10: TTB | AD10: TTB by income source | AH10: Decomposition of TTB in pp | AQ10: Decomposition of fiscal drag in percentage | AZ10: OECD estimates | CC10: Ratio8020 all income | CK10: Gini tax base (from Table 3.1) | CS10: Ratio8020 tax base | DA10: Kakwani (from Table 3.2) | DD10: Share taxpayers | EA10: 2023 Personal Income Tax Revenue | EN10: 2023 Tax Base (il_fiscaldrag_all) | EV10: 2023 TTB | EZ10: 2023 Share taxpayers | FB10: 2023 TTB by income source
B11: Decile | C11: Original | D11: Incomes grow 1% | E11: Incomes & all parameters grow 1% | F11: Incomes & (only) tax brackets grow 1% | G11: Incomes & (only) tax brackets and tax benefit #1 grow 1% | H11: Incomes & tax brackets and tax benefit #1 & 2 grow 1% | I11: Incomes & tax brackets and tax benefit #1 & 2 & 3 grow 1% | K11: Labor income grows 1% | L11: Benefits and pensions grow 1% | M11: Self-employment income grows 1% | N11: Capital income grows 1% | O11: Share of total tax liability | P11: Original | Q11: Incomes grow 1% | R11: Relative change (should be 1%) | S11: Labor income grows 1% | T11: Benefits and pensions grow 1% | U11: Self-employment income grows 1% | V11: Capital income grows 1% | W11: Incomes grow 1% | X11: Incomes & all parameters grow 1% | Y11: Incomes & tax brackets grow 1% | Z11: Incomes & tax brackets and tax benefit #1 grow 1% | AA11: Incomes & tax brackets and tax benefit #1 & 2 grow 1% | AB11: Incomes & tax brackets and tax benefit #1 & 2 & 3 grow 1% | AC11: Incomes & tax brackets and tax benefit #1 & 2 & 3 & 4 grow 1% | AD11: Labor income grows 1% | AE11: Benefits and pensions grow 1% | AF11: Self-employment income grows 1% | AG11: Capital income grows 1% | AH11: Proportional effect | AI11: Residual | AJ11: By bracket progressivity | AK11: By tax benefit 1 | AL11: By tax benefit 2 | AM11: By tax benefit 3 | AN11: By tax benefit 4 | AO11: By other tax benefits | AP11: By other tax benefits and residual | AQ11: Proportional effect | AR11: Residual | AS11: By bracket progressivity | AT11: By tax benefit 1 | AU11: By tax benefit 2 | AV11: By tax benefit 3 | AX11: By other tax benefits | AY11: By other tax benefits and residual | AZ11: TTB all incomes | BA11: TTB earnings | BB11: TTB self-empl. | BC11: TTB capital | BD11: Diff. all incomes (pp) | BE11: Diff. earnings (pp) | BF11: Diff. self-empl. (pp) | BG11: Diff. capital (pp) | BH11: Labour income | BI11: Pension and benefits | BJ11: Self-employment income | BK11: Capital income | BL11: Share of labour income | BM11: Share of pension and benefits | BN11: Share of self-employment income | BO11: Share of capital income | BP11: TTB without pensions | BQ11: Diff TTB TTB_nopens | BR11: Diff TTB_nopens TTB_OECD | BS11: Share of total tax base | CC11: Ratio8020 all income preincrease pretax | CD11: Ratio8020 all income preincrease posttax | CE11: Ratio8020 all income postincrease pretax | CF11: Ratio8020 all income postincrease posttax | CG11: Ratio8020 allinc increase preincrease | CH11: Ratio8020 allinc increase postincrease | CI11: Diff Ratio8020 change allinc (pp) | CJ11: Diff Ratio8020 allinc postax (pp) | CK11: Gini tax base preincrease pretax | CL11: Gini tax base preincrease posttax | CM11: Gini tax base postincrease pretax | CN11: Gini tax base postincrease posttax | CO11: Gini taxinc reduction preincrease | CP11: Gini taxinc reduction postincrease | CQ11: Diff Gini reduction taxinc (pp) | CR11: Diff Gini tax base posttax | CS11: Ratio8020 tax base preincrease pretax | CT11: Ratio8020 tax base preincrease posttax | CU11: Ratio8020 tax base postincrease pretax | CV11: Ratio8020 tax base postincrease posttax | CW11: Ratio8020 taxinc decrease preincrease | CX11: Ratio8020 taxinc decrease postincrease | CY11: Diff Ratio8020 change taxinc (pp) | CZ11: Diff Ratio8020 taxinc postax (pp) | DA11: kawani taxinc preincrease | DB11: kawani taxinc postincrease | DC11: Diff kakwani taxinc | DD11: Share with zero tax liability (right axis) | DE11: Share with non-zero tax liability | EA11: 2023 Original | EB11: 2023 Incomes grow 1% | EC11: 2023 Incomes & all parameters grow 1% | ED11: 2023 Incomes & (only) tax brackets grow 1% | EE11: 2023 Incomes & (only) tax brackets and tax benefit #1 grow 1% | EF11: 2023 Incomes & tax brackets and tax benefit #1 & 2 grow 1% | EG11: 2023 Incomes & tax brackets and tax benefit #1 & 2 & 3 grow 1% | EI11: 2023 Labor income grows 1% | EJ11: 2023 Benefits and pensions grow 1% | EK11: 2023 Self-employment income grows 1% | EL11: 2023 Capital income grows 1% | EM11: Share of total tax liability | EN11: 2023 Original | EO11: 2023 Incomes grow 1% | EP11: 2023 Relative change (should be 1%) | EQ11: 2023 Labor income grows 1% | ER11: 2023 Benefits and pensions grow 1% | ES11: 2023 Self-employment income grows 1% | ET11: 2023 Capital income grows 1% | EU11: 2023 Share of total tax base | EV11: 2023 TTB Incomes grow 1% | EW11: 2023 Incomes & all parameters grow 1% | EX11: 2023 Diff residual (pp) | EY11: 2023 TTB change | EZ11: 2023 Share with zero tax liability (right axis) | FA11: 2023 Share with non-zero tax liability | FB11: 2023 TTB Labor income grows 1% | FC11: 2023 TTB Benefits and pensions grow 1% | FD11: 2023 TTB Self-employment income grows 1% | FE11: 2023 TTB Capital income grows 1% | FF11: 2023 TTB change Labor | FG11: 2023 TTB change Benefits and pensions | FH11: 2023 TTB change Self-employment income | FI11: 2023 TTB change Capital
B12: 1 | C12: {='[2]2. Distributional by deciles o'!$B$82:$G$92} -> -1.5702069e+08 | D12: -1.5615024e+08 | E12: -1.5859483e+08 | F12: -1.5688058e+08 | G12: -1.5718223e+08 | H12: -1.5725564e+08 | K12: - | L12: - | M12: - | N12: - | O12: =C12/C$22*100 -> -0.44734438 | P12: {='[2]2. Distributional by deciles o'!$B$100:$C$110} -> 3.2257884e+09 | Q12: 3.2580468e+09 | R12: =(Q12/P12-1)*100 -> 1.0000148 | S12: - | T12: - | U12: - | V12: - | W12: =IF(D12<>0,((D12-$C12)/ABS($C12)) / ($Q12/$P12-1),0) -> 0.55434579 | X12: =IF(E12<>0,((E12-$C12)/ABS($C12)) / ($Q12/$P12-1),0) -> -1.0024891 | Y12: =IF(F12<>0,MAX(((F12-$C12)/ABS($C12)) / ($Q12/$P12-1),0),0) -> 0.089229866 | Z12: =IF(G12<>0,MAX(((G12-$C12)/ABS($C12)) / ($Q12/$P12-1),0),0) -> 0 | AA12: =IF(H12<>0,MAX(((H12-$C12)/ABS($C12)) / ($Q12/$P12-1),0),0) -> 0 | AB12: =IF(I12<>0,MAX(((I12-$C12)/ABS($C12)) / ($Q12/$P12-1),0),AA12) -> 0 | AC12: =IF(J12<>0,MAX(((J12-$C12)/ABS($C12)) / ($Q12/$P12-1),0),AB12) -> 0 | AD12: - | AE12: - | AF12: - | AG12: - | AH12: =MIN(W12,1) -> 0.55434579 | AI12: =IF(W12>1,MAX(W12-SUM(AH12,AJ12:AO12),0),0) -> 0 | AJ12: =IF(W12>1,MIN($W12-Y12,W12-AH12),0) -> 0 | AK12: =IF(W12>1,MAX(MIN(Y12-Z12,W12-AH12-AJ12),0),0) -> 0 | AL12: =IF(W12>1,MAX(MIN(Z12-AA12,W12-AH12-AJ12-AK12),0),0) -> 0 | AM12: =IF(I12<>0,IF(W12>1,MAX(MIN(AA12-AB12,W12-AH12-AJ12-AK12-AL12),0),0),0) -> 0 | AN12: =IF(J12<>0,IF(W12>1,MAX(MIN(AB12-AC12,W12-AH12-AJ12-AK12-AL12-AM12),0),0),0) -> 0 | AO12: =IF(W12>1,MAX(0,MIN(W12-AH12-AJ12-AK12-AL12-AM12,W12-AH12-AJ12-AK12-AL12-AM12-X12+1)),0) -> 0 | AP12: =AI12+AO12 -> 0 | AQ12: - | AR12: =AI12/($W12-1)*100 -> 0 | AS12: =AJ12/($W12-1)*100 -> 0 | AT12: =AK12/($W12-1)*100 -> 0 | AU12: =AL12/($W12-1)*100 -> 0 | AV12: =AM12/($W12-1)*100 -> 0 | AW12: =AN12/($W12-1)*100 -> 0 | AX12: =AO12/($W12-1)*100 -> 0 | AY12: =AP12/($W12-1)*100 -> 0 | AZ12: - | BA12: - | BB12: - | BC12: - | BD12: - | BE12: - | BF12: - | BG12: - | BH12: {='[2]2. Distributional by deciles o'!$B$118:$B$128} -> 1.870474e+09 | BI12: {='[2]2. Distributional by deciles o'!$B$136:$B$146} -> 9.4220443e+08 | BJ12: {='[2]2. Distributional by deciles o'!$B$154:$B$164} -> 2.7071392e+08 | BK12: {='[2]2. Distributional by deciles o'!$B$172:$B$182} -> 1.4239577e+08 | BL12: =BH12/SUM($BH12:$BK12) -> 0.57985023 | BM12: =BI12/SUM($BH12:$BK12) -> 0.29208504 | BN12: =BJ12/SUM($BH12:$BK12) -> 0.083921793 | BO12: =BK12/SUM($BH12:$BK12) -> 0.044142939 | BP12: - | BQ12: - | BR12: - | BS12: =P12/P$22*100 -> 1.2309505 | CC12: - | CD12: - | CE12: - | CF12: - | CG12: - | CH12: - | CI12: - | CK12: - | CL12: - | CM12: - | CN12: - | CO12: - | CP12: - | CQ12: - | CS12: - | CT12: - | CU12: - | CV12: - | CW12: - | CX12: - | CY12: - | DA12: - | DB12: - | DC12: - | DD12: =(1-DE12)*100 -> 17.164668 | DE12: {='[2]2. Distributional by deciles o'!$M$10:$M$20} -> 0.82835332 | EA12: {='[3]2. Distributional by deciles o'!$B$82:$H$92} -> -2.9403817e+08 | EB12: -2.9336951e+08 | EC12: -2.969286e+08 | ED12: -2.9435276e+08 | EE12: -2.9546264e+08 | EF12: -2.9553617e+08 | EG12: -2.9350792e+08 | EI12: - | EJ12: - | EK12: - | EL12: - | EM12: =EA12/EA$22*100 -> -0.74784531 | EN12: {='[3]2. Distributional by deciles o'!$B$100:$C$110} -> 3.7517771e+09 | EO12: 3.7892945e+09 | EP12: =(EO12/EN12-1)*100 -> 0.99999005 | EQ12: - | ER12: - | ES12: - | ET12: - | EU12: =EN12/EN$22*100 -> 1.2228736 | EV12: =((EB12-$EA12)/ABS($EA12)) / ($EO12/$EN12-1) -> 0.22740673 | EW12: =IF(EC12<>0,((EC12-$EA12)/ABS($EA12)) / ($EO12/$EN12-1),0) -> -0.9830214 | EY12: =EV12-W12 -> -0.32693906 | EZ12: =(1-FA12)*100 -> 15.580745 | FA12: {='[3]2. Distributional by deciles o'!$L$10:$L$20} -> 0.84419255 | FB12: - | FC12: - | FD12: - | FE12: - | FF12: - | FG12: - | FH12: - | FI12: -
B13: 2 | C13: 26423258 | D13: 36796737 | E13: 26681814 | F13: 29820420 | G13: 28947728 | H13: 28621805 | K13: - | L13: - | M13: - | N13: - | O13: =C13/C$22*100 -> 0.075278591 | P13: 1.037195e+10 | Q13: 1.047567e+10 | R13: =(Q13/P13-1)*100 -> 0.99999922 | S13: - | T13: - | U13: - | V13: - | W13: =IF(D13<>0,((D13-$C13)/ABS($C13)) / ($Q13/$P13-1),0) -> 39.258922 | X13: =IF(E13<>0,((E13-$C13)/ABS($C13)) / ($Q13/$P13-1),0) -> 0.97851517 | Y13: =IF(F13<>0,MAX(((F13-$C13)/ABS($C13)) / ($Q13/$P13-1),0),0) -> 12.856719 | Z13: =IF(G13<>0,MAX(((G13-$C13)/ABS($C13)) / ($Q13/$P13-1),0),0) -> 9.5539736 | AA13: =IF(H13<>0,MAX(((H13-$C13)/ABS($C13)) / ($Q13/$P13-1),0),0) -> 8.3205042 | AB13: =IF(I13<>0,MAX(((I13-$C13)/ABS($C13)) / ($Q13/$P13-1),0),AA13) -> 8.3205042 | AC13: =IF(J13<>0,MAX(((J13-$C13)/ABS($C13)) / ($Q13/$P13-1),0),AB13) -> 8.3205042 | AD13: - | AE13: - | AF13: - | AG13: - | AH13: =MIN(W13,1) -> 1 | AI13: =IF(W13>1,MAX(W13-SUM(AH13,AJ13:AO13),0),0) -> 0 | AJ13: =IF(W13>1,MIN($W13-Y13,W13-AH13),0) -> 26.402203 | AK13: =IF(W13>1,MAX(MIN(Y13-Z13,W13-AH13-AJ13),0),0) -> 3.3027456 | AL13: =IF(W13>1,MAX(MIN(Z13-AA13,W13-AH13-AJ13-AK13),0),0) -> 1.2334693 | AM13: =IF(I13<>0,IF(W13>1,MAX(MIN(AA13-AB13,W13-AH13-AJ13-AK13-AL13),0),0),0) -> 0 | AN13: =IF(J13<>0,IF(W13>1,MAX(MIN(AB13-AC13,W13-AH13-AJ13-AK13-AL13-AM13),0),0),0) -> 0 | AO13: =IF(W13>1,MAX(0,MIN(W13-AH13-AJ13-AK13-AL13-AM13,W13-AH13-AJ13-AK13-AL13-AM13-X13+1)),0) -> 7.3205042 | AP13: =AI13+AO13 -> 7.3205042 | AQ13: - | AR13: =AI13/($W13-1)*100 -> 0 | AS13: =AJ13/($W13-1)*100 -> 69.00927 | AT13: =AK13/($W13-1)*100 -> 8.6326153 | AU13: =AL13/($W13-1)*100 -> 3.2240044 | AV13: =AM13/($W13-1)*100 -> 0 | AW13: =AN13/($W13-1)*100 -> 0 | AX13: =AO13/($W13-1)*100 -> 19.13411 | AY13: =AP13/($W13-1)*100 -> 19.13411 | AZ13: - | BA13: - | BB13: - | BC13: - | BD13: - | BE13: - | BF13: - | BG13: - | BH13: 4.2957874e+09 | BI13: 5.1463495e+09 | BJ13: 7.4251444e+08 | BK13: 1.8730013e+08 | BL13: =BH13/SUM($BH13:$BK13) -> 0.41417349 | BM13: =BI13/SUM($BH13:$BK13) -> 0.49617948 | BN13: =BJ13/SUM($BH13:$BK13) -> 0.071588692 | BO13: =BK13/SUM($BH13:$BK13) -> 0.018058331 | BP13: - | BQ13: - | BR13: - | BS13: =P13/P$22*100 -> 3.9579029 | CC13: - | CD13: - | CE13: - | CF13: - | CG13: - | CH13: - | CI13: - | CK13: - | CL13: - | CM13: - | CN13: - | CO13: - | CP13: - | CQ13: - | CS13: - | CT13: - | CU13: - | CV13: - | CW13: - | CX13: - | CY13: - | DA13: - | DB13: - | DC13: - | DD13: =(1-DE13)*100 -> 14.776201 | DE13: 0.85223799 | EA13: -1.701921e+08 | EB13: -1.5746408e+08 | EC13: -1.7187851e+08 | ED13: -1.6574578e+08 | EE13: -1.6658925e+08 | EF13: -1.7613939e+08 | EG13: -1.654674e+08 | EI13: - | EJ13: - | EK13: - | EL13: - | EM13: =EA13/EA$22*100 -> -0.43286001 | EN13: 1.2216853e+10 | EO13: 1.2339022e+10 | EP13: =(EO13/EN13-1)*100 -> 1.0000017 | EQ13: - | ER13: - | ES13: - | ET13: - | EU13: =EN13/EN$22*100 -> 3.9820242 | EV13: =((EB13-$EA13)/ABS($EA13)) / ($EO13/$EN13-1) -> 7.4786083 | EW13: =IF(EC13<>0,((EC13-$EA13)/ABS($EA13)) / ($EO13/$EN13-1),0) -> -0.9908824 | EY13: =EV13-W13 -> -31.780314 | EZ13: =(1-FA13)*100 -> 0.47940527 | FA13: 0.99520595 | FB13: - | FC13: - | FD13: - | FE13: - | FF13: - | FG13: - | FH13: - | FI13: -
B14: 3 | C14: 5.3322438e+08 | D14: 5.5899296e+08 | E14: 5.3855277e+08 | F14: 5.4434209e+08 | G14: 5.4169153e+08 | H14: 5.4083676e+08 | K14: - | L14: - | M14: - | N14: - | O14: =C14/C$22*100 -> 1.5191306 | P14: 1.4137687e+10 | Q14: 1.4279066e+10 | R14: =(Q14/P14-1)*100 -> 1.0000148 | S14: - | T14: - | U14: - | V14: - | W14: =IF(D14<>0,((D14-$C14)/ABS($C14)) / ($Q14/$P14-1),0) -> 4.8325244 | X14: =IF(E14<>0,((E14-$C14)/ABS($C14)) / ($Q14/$P14-1),0) -> 0.99926321 | Y14: =IF(F14<>0,MAX(((F14-$C14)/ABS($C14)) / ($Q14/$P14-1),0),0) -> 2.0849665 | Z14: =IF(G14<>0,MAX(((G14-$C14)/ABS($C14)) / ($Q14/$P14-1),0),0) -> 1.5878912 | AA14: =IF(H14<>0,MAX(((H14-$C14)/ABS($C14)) / ($Q14/$P14-1),0),0) -> 1.4275914 | AB14: =IF(I14<>0,MAX(((I14-$C14)/ABS($C14)) / ($Q14/$P14-1),0),AA14) -> 1.4275914 | AC14: =IF(J14<>0,MAX(((J14-$C14)/ABS($C14)) / ($Q14/$P14-1),0),AB14) -> 1.4275914 | AD14: - | AE14: - | AF14: - | AG14: - | AH14: =MIN(W14,1) -> 1 | AI14: =IF(W14>1,MAX(W14-SUM(AH14,AJ14:AO14),0),0) -> 8.8817842e-16 | AJ14: =IF(W14>1,MIN($W14-Y14,W14-AH14),0) -> 2.7475579 | AK14: =IF(W14>1,MAX(MIN(Y14-Z14,W14-AH14-AJ14),0),0) -> 0.49707531 | AL14: =IF(W14>1,MAX(MIN(Z14-AA14,W14-AH14-AJ14-AK14),0),0) -> 0.16029971 | AM14: =IF(I14<>0,IF(W14>1,MAX(MIN(AA14-AB14,W14-AH14-AJ14-AK14-AL14),0),0),0) -> 0 | AN14: =IF(J14<>0,IF(W14>1,MAX(MIN(AB14-AC14,W14-AH14-AJ14-AK14-AL14-AM14),0),0),0) -> 0 | AO14: =IF(W14>1,MAX(0,MIN(W14-AH14-AJ14-AK14-AL14-AM14,W14-AH14-AJ14-AK14-AL14-AM14-X14+1)),0) -> 0.42759144 | AP14: =AI14+AO14 -> 0.42759144 | AQ14: - | AR14: =AI14/($W14-1)*100 -> 2.3174762e-14 | AS14: =AJ14/($W14-1)*100 -> 71.690553 | AT14: =AK14/($W14-1)*100 -> 12.969919 | AU14: =AL14/($W14-1)*100 -> 4.1826143 | AV14: =AM14/($W14-1)*100 -> 0 | AW14: =AN14/($W14-1)*100 -> 0 | AX14: =AO14/($W14-1)*100 -> 11.156914 | AY14: =AP14/($W14-1)*100 -> 11.156914 | AZ14: - | BA14: - | BB14: - | BC14: - | BD14: - | BE14: - | BF14: - | BG14: - | BH14: 8.0552016e+09 | BI14: 5.1172231e+09 | BJ14: 7.0143093e+08 | BK14: 2.6383252e+08 | BL14: =BH14/SUM($BH14:$BK14) -> 0.56976795 | BM14: =BI14/SUM($BH14:$BK14) -> 0.36195615 | BN14: =BJ14/SUM($BH14:$BK14) -> 0.049614259 | BO14: =BK14/SUM($BH14:$BK14) -> 0.018661645 | BP14: - | BQ14: - | BR14: - | BS14: =P14/P$22*100 -> 5.3948959 | CC14: - | CD14: - | CE14: - | CF14: - | CG14: - | CH14: - | CI14: - | CK14: - | CL14: - | CM14: - | CN14: - | CO14: - | CP14: - | CQ14: - | CS14: - | CT14: - | CU14: - | CV14: - | CW14: - | CX14: - | CY14: - | DA14: - | DB14: - | DC14: - | DD14: =(1-DE14)*100 -> 0 | DE14: 1 | EA14: 4.1304447e+08 | EB14: 4.4320389e+08 | EC14: 4.1713549e+08 | ED14: 4.2758131e+08 | EE14: 4.2450556e+08 | EF14: 4.2217075e+08 | EG14: 4.2837965e+08 | EI14: - | EJ14: - | EK14: - | EL14: - | EM14: =EA14/EA$22*100 -> 1.0505213 | EN14: 1.6653157e+10 | EO14: 1.681969e+10 | EP14: =(EO14/EN14-1)*100 -> 1.0000042 | EQ14: - | ER14: - | ES14: - | ET14: - | EU14: =EN14/EN$22*100 -> 5.4280161 | EV14: =((EB14-$EA14)/ABS($EA14)) / ($EO14/$EN14-1) -> 7.3017073 | EW14: =IF(EC14<>0,((EC14-$EA14)/ABS($EA14)) / ($EO14/$EN14-1),0) -> 0.9904509 | EY14: =EV14-W14 -> 2.469183 | EZ14: =(1-FA14)*100 -> 0 | FA14: 1 | FB14: - | FC14: - | FD14: - | FE14: - | FF14: - | FG14: - | FH14: - | FI14: -
B15: 4 | C15: 1.0527935e+09 | D15: 1.0894493e+09 | E15: 1.0633183e+09 | F15: 1.0694568e+09 | G15: 1.0667283e+09 | H15: 1.0656674e+09 | K15: - | L15: - | M15: - | N15: - | O15: =C15/C$22*100 -> 2.999358 | P15: 1.7268543e+10 | Q15: 1.7441226e+10 | R15: =(Q15/P15-1)*100 -> 0.9999898 | S15: - | T15: - | U15: - | V15: - | W15: =IF(D15<>0,((D15-$C15)/ABS($C15)) / ($Q15/$P15-1),0) -> 3.4818014 | X15: =IF(E15<>0,((E15-$C15)/ABS($C15)) / ($Q15/$P15-1),0) -> 0.9997108 | Y15: =IF(F15<>0,MAX(((F15-$C15)/ABS($C15)) / ($Q15/$P15-1),0),0) -> 1.5827847 | Z15: =IF(G15<>0,MAX(((G15-$C15)/ABS($C15)) / ($Q15/$P15-1),0),0) -> 1.323612 | AA15: =IF(H15<>0,MAX(((H15-$C15)/ABS($C15)) / ($Q15/$P15-1),0),0) -> 1.222841 | AB15: =IF(I15<>0,MAX(((I15-$C15)/ABS($C15)) / ($Q15/$P15-1),0),AA15) -> 1.222841 | AC15: =IF(J15<>0,MAX(((J15-$C15)/ABS($C15)) / ($Q15/$P15-1),0),AB15) -> 1.222841 | AD15: - | AE15: - | AF15: - | AG15: - | AH15: =MIN(W15,1) -> 1 | AI15: =IF(W15>1,MAX(W15-SUM(AH15,AJ15:AO15),0),0) -> 0 | AJ15: =IF(W15>1,MIN($W15-Y15,W15-AH15),0) -> 1.8990167 | AK15: =IF(W15>1,MAX(MIN(Y15-Z15,W15-AH15-AJ15),0),0) -> 0.25917271 | AL15: =IF(W15>1,MAX(MIN(Z15-AA15,W15-AH15-AJ15-AK15),0),0) -> 0.10077101 | AM15: =IF(I15<>0,IF(W15>1,MAX(MIN(AA15-AB15,W15-AH15-AJ15-AK15-AL15),0),0),0) -> 0 | AN15: =IF(J15<>0,IF(W15>1,MAX(MIN(AB15-AC15,W15-AH15-AJ15-AK15-AL15-AM15),0),0),0) -> 0 | AO15: =IF(W15>1,MAX(0,MIN(W15-AH15-AJ15-AK15-AL15-AM15,W15-AH15-AJ15-AK15-AL15-AM15-X15+1)),0) -> 0.22284095 | AP15: =AI15+AO15 -> 0.22284095 | AQ15: - | AR15: =AI15/($W15-1)*100 -> 0 | AS15: =AJ15/($W15-1)*100 -> 76.517675 | AT15: =AK15/($W15-1)*100 -> 10.442927 | AU15: =AL15/($W15-1)*100 -> 4.0603978 | AV15: =AM15/($W15-1)*100 -> 0 | AW15: =AN15/($W15-1)*100 -> 0 | AX15: =AO15/($W15-1)*100 -> 8.9790004 | AY15: =AP15/($W15-1)*100 -> 8.9790004 | AZ15: - | BA15: - | BB15: - | BC15: - | BD15: - | BE15: - | BF15: - | BG15: - | BH15: 9.624971e+09 | BI15: 6.2099844e+09 | BJ15: 1.1355477e+09 | BK15: 2.9803988e+08 | BL15: =BH15/SUM($BH15:$BK15) -> 0.55737019 | BM15: =BI15/SUM($BH15:$BK15) -> 0.35961253 | BN15: =BJ15/SUM($BH15:$BK15) -> 0.065758162 | BO15: =BK15/SUM($BH15:$BK15) -> 0.017259122 | BP15: - | BQ15: - | BR15: - | BS15: =P15/P$22*100 -> 6.5896205 | CC15: - | CD15: - | CE15: - | CF15: - | CG15: - | CH15: - | CI15: - | CK15: - | CL15: - | CM15: - | CN15: - | CO15: - | CP15: - | CQ15: - | CS15: - | CT15: - | CU15: - | CV15: - | CW15: - | CX15: - | CY15: - | DA15: - | DB15: - | DC15: - | DD15: =(1-DE15)*100 -> 0 | DE15: 1 | EA15: 1.0158175e+09 | EB15: 1.0591615e+09 | EC15: 1.0259197e+09 | ED15: 1.0372811e+09 | EE15: 1.0336835e+09 | EF15: 1.0319477e+09 | EG15: 1.0389004e+09 | EI15: - | EJ15: - | EK15: - | EL15: - | EM15: =EA15/EA$22*100 -> 2.5835909 | EN15: 2.0117273e+10 | EO15: 2.0318446e+10 | EP15: =(EO15/EN15-1)*100 -> 0.99999901 | EQ15: - | ER15: - | ES15: - | ET15: - | EU15: =EN15/EN$22*100 -> 6.5571279 | EV15: =((EB15-$EA15)/ABS($EA15)) / ($EO15/$EN15-1) -> 4.2669179 | EW15: =IF(EC15<>0,((EC15-$EA15)/ABS($EA15)) / ($EO15/$EN15-1),0) -> 0.99449848 | EY15: =EV15-W15 -> 0.78511653 | EZ15: =(1-FA15)*100 -> 0.44253136 | FA15: 0.99557469 | FB15: - | FC15: - | FD15: - | FE15: - | FF15: - | FG15: - | FH15: - | FI15: -
B16: 5 | C16: 1.6073541e+09 | D16: 1.6523379e+09 | E16: 1.6234242e+09 | F16: 1.6293881e+09 | G16: 1.6268633e+09 | H16: 1.6256115e+09 | K16: - | L16: - | M16: - | N16: - | O16: =C16/C$22*100 -> 4.5792745 | P16: 2.0486801e+10 | Q16: 2.0691668e+10 | R16: =(Q16/P16-1)*100 -> 0.99999151 | S16: - | T16: - | U16: - | V16: - | W16: =IF(D16<>0,((D16-$C16)/ABS($C16)) / ($Q16/$P16-1),0) -> 2.7986468 | X16: =IF(E16<>0,((E16-$C16)/ABS($C16)) / ($Q16/$P16-1),0) -> 0.9997939 | Y16: =IF(F16<>0,MAX(((F16-$C16)/ABS($C16)) / ($Q16/$P16-1),0),0) -> 1.3708365 | Z16: =IF(G16<>0,MAX(((G16-$C16)/ABS($C16)) / ($Q16/$P16-1),0),0) -> 1.2137538 | AA16: =IF(H16<>0,MAX(((H16-$C16)/ABS($C16)) / ($Q16/$P16-1),0),0) -> 1.1358749 | AB16: =IF(I16<>0,MAX(((I16-$C16)/ABS($C16)) / ($Q16/$P16-1),0),AA16) -> 1.1358749 | AC16: =IF(J16<>0,MAX(((J16-$C16)/ABS($C16)) / ($Q16/$P16-1),0),AB16) -> 1.1358749 | AD16: - | AE16: - | AF16: - | AG16: - | AH16: =MIN(W16,1) -> 1 | AI16: =IF(W16>1,MAX(W16-SUM(AH16,AJ16:AO16),0),0) -> 0 | AJ16: =IF(W16>1,MIN($W16-Y16,W16-AH16),0) -> 1.4278102 | AK16: =IF(W16>1,MAX(MIN(Y16-Z16,W16-AH16-AJ16),0),0) -> 0.15708273 | AL16: =IF(W16>1,MAX(MIN(Z16-AA16,W16-AH16-AJ16-AK16),0),0) -> 0.077878924 | AM16: =IF(I16<>0,IF(W16>1,MAX(MIN(AA16-AB16,W16-AH16-AJ16-AK16-AL16),0),0),0) -> 0 | AN16: =IF(J16<>0,IF(W16>1,MAX(MIN(AB16-AC16,W16-AH16-AJ16-AK16-AL16-AM16),0),0),0) -> 0 | AO16: =IF(W16>1,MAX(0,MIN(W16-AH16-AJ16-AK16-AL16-AM16,W16-AH16-AJ16-AK16-AL16-AM16-X16+1)),0) -> 0.1358749 | AP16: =AI16+AO16 -> 0.1358749 | AQ16: - | AR16: =AI16/($W16-1)*100 -> 0 | AS16: =AJ16/($W16-1)*100 -> 79.382469 | AT16: =AK16/($W16-1)*100 -> 8.733384 | AU16: =AL16/($W16-1)*100 -> 4.329862 | AV16: =AM16/($W16-1)*100 -> 0 | AW16: =AN16/($W16-1)*100 -> 0 | AX16: =AO16/($W16-1)*100 -> 7.5542845 | AY16: =AP16/($W16-1)*100 -> 7.5542845 | AZ16: - | BA16: - | BB16: - | BC16: - | BD16: - | BE16: - | BF16: - | BG16: - | BH16: 1.2203248e+10 | BI16: 6.5263722e+09 | BJ16: 1.4978513e+09 | BK16: 2.59329e+08 | BL16: =BH16/SUM($BH16:$BK16) -> 0.59566392 | BM16: =BI16/SUM($BH16:$BK16) -> 0.31856474 | BN16: =BJ16/SUM($BH16:$BK16) -> 0.073112996 | BO16: =BK16/SUM($BH16:$BK16) -> 0.012658346 | BP16: - | BQ16: - | BR16: - | BS16: =P16/P$22*100 -> 7.8176977 | CC16: - | CD16: - | CE16: - | CF16: - | CG16: - | CH16: - | CI16: - | CK16: - | CL16: - | CM16: - | CN16: - | CO16: - | CP16: - | CQ16: - | CS16: - | CT16: - | CU16: - | CV16: - | CW16: - | CX16: - | CY16: - | DA16: - | DB16: - | DC16: - | DD16: =(1-DE16)*100 -> 0 | DE16: 1 | EA16: 1.6605394e+09 | EB16: 1.7130265e+09 | EC16: 1.6771342e+09 | ED16: 1.6876355e+09 | EE16: 1.6841252e+09 | EF16: 1.6827738e+09 | EG16: 1.6905705e+09 | EI16: - | EJ16: - | EK16: - | EL16: - | EM16: =EA16/EA$22*100 -> 4.2233517 | EN16: 2.3902111e+10 | EO16: 2.414113e+10 | EP16: =(EO16/EN16-1)*100 -> 0.99999055 | EQ16: - | ER16: - | ES16: - | ET16: - | EU16: =EN16/EN$22*100 -> 7.7907775 | EV16: =((EB16-$EA16)/ABS($EA16)) / ($EO16/$EN16-1) -> 3.1608782 | EW16: =IF(EC16<>0,((EC16-$EA16)/ABS($EA16)) / ($EO16/$EN16-1),0) -> 0.99937028 | EY16: =EV16-W16 -> 0.36223142 | EZ16: =(1-FA16)*100 -> 0 | FA16: 1 | FB16: - | FC16: - | FD16: - | FE16: - | FF16: - | FG16: - | FH16: - | FI16: -
B17: 6 | C17: 2.2988003e+09 | D17: 2.3539824e+09 | E17: 2.3217857e+09 | F17: 2.3271094e+09 | G17: 2.3247358e+09 | H17: 2.323221e+09 | K17: - | L17: - | M17: - | N17: - | O17: =C17/C$22*100 -> 6.5491714 | P17: 2.3783687e+10 | Q17: 2.4021525e+10 | R17: =(Q17/P17-1)*100 -> 1.000003 | S17: - | T17: - | U17: - | V17: - | W17: =IF(D17<>0,((D17-$C17)/ABS($C17)) / ($Q17/$P17-1),0) -> 2.4004676 | X17: =IF(E17<>0,((E17-$C17)/ABS($C17)) / ($Q17/$P17-1),0) -> 0.99988319 | Y17: =IF(F17<>0,MAX(((F17-$C17)/ABS($C17)) / ($Q17/$P17-1),0),0) -> 1.2314699 | Z17: =IF(G17<>0,MAX(((G17-$C17)/ABS($C17)) / ($Q17/$P17-1),0),0) -> 1.1282165 | AA17: =IF(H17<>0,MAX(((H17-$C17)/ABS($C17)) / ($Q17/$P17-1),0),0) -> 1.0623216 | AB17: =IF(I17<>0,MAX(((I17-$C17)/ABS($C17)) / ($Q17/$P17-1),0),AA17) -> 1.0623216 | AC17: =IF(J17<>0,MAX(((J17-$C17)/ABS($C17)) / ($Q17/$P17-1),0),AB17) -> 1.0623216 | AD17: - | AE17: - | AF17: - | AG17: - | AH17: =MIN(W17,1) -> 1 | AI17: =IF(W17>1,MAX(W17-SUM(AH17,AJ17:AO17),0),0) -> 0 | AJ17: =IF(W17>1,MIN($W17-Y17,W17-AH17),0) -> 1.1689978 | AK17: =IF(W17>1,MAX(MIN(Y17-Z17,W17-AH17-AJ17),0),0) -> 0.1032534 | AL17: =IF(W17>1,MAX(MIN(Z17-AA17,W17-AH17-AJ17-AK17),0),0) -> 0.065894872 | AM17: =IF(I17<>0,IF(W17>1,MAX(MIN(AA17-AB17,W17-AH17-AJ17-AK17-AL17),0),0),0) -> 0 | AN17: =IF(J17<>0,IF(W17>1,MAX(MIN(AB17-AC17,W17-AH17-AJ17-AK17-AL17-AM17),0),0),0) -> 0 | AO17: =IF(W17>1,MAX(0,MIN(W17-AH17-AJ17-AK17-AL17-AM17,W17-AH17-AJ17-AK17-AL17-AM17-X17+1)),0) -> 0.062321591 | AP17: =AI17+AO17 -> 0.062321591 | AQ17: - | AR17: =AI17/($W17-1)*100 -> 0 | AS17: =AJ17/($W17-1)*100 -> 83.471959 | AT17: =AK17/($W17-1)*100 -> 7.3727799 | AU17: =AL17/($W17-1)*100 -> 4.7052049 | AV17: =AM17/($W17-1)*100 -> 0 | AW17: =AN17/($W17-1)*100 -> 0 | AX17: =AO17/($W17-1)*100 -> 4.4500558 | AY17: =AP17/($W17-1)*100 -> 4.4500558 | AZ17: - | BA17: - | BB17: - | BC17: - | BD17: - | BE17: - | BF17: - | BG17: - | BH17: 1.5285858e+10 | BI17: 7.1799095e+09 | BJ17: 1.0490029e+09 | BK17: 2.6891777e+08 | BL17: =BH17/SUM($BH17:$BK17) -> 0.64270343 | BM17: =BI17/SUM($BH17:$BK17) -> 0.30188377 | BN17: =BJ17/SUM($BH17:$BK17) -> 0.044105982 | BO17: =BK17/SUM($BH17:$BK17) -> 0.011306815 | BP17: - | BQ17: - | BR17: - | BS17: =P17/P$22*100 -> 9.0757787 | CC17: - | CD17: - | CE17: - | CF17: - | CG17: - | CH17: - | CI17: - | CK17: - | CL17: - | CM17: - | CN17: - | CO17: - | CP17: - | CQ17: - | CS17: - | CT17: - | CU17: - | CV17: - | CW17: - | CX17: - | CY17: - | DA17: - | DB17: - | DC17: - | DD17: =(1-DE17)*100 -> 0 | DE17: 1 | EA17: 2.4529152e+09 | EB17: 2.516948e+09 | EC17: 2.477414e+09 | ED17: 2.4862696e+09 | EE17: 2.4831993e+09 | EF17: 2.4815872e+09 | EG17: 2.4916474e+09 | EI17: - | EJ17: - | EK17: - | EL17: - | EM17: =EA17/EA$22*100 -> 6.2386496 | EN17: 2.7869725e+10 | EO17: 2.8148421e+10 | EP17: =(EO17/EN17-1)*100 -> 0.99999756 | EQ17: - | ER17: - | ES17: - | ET17: - | EU17: =EN17/EN$22*100 -> 9.084002 | EV17: =((EB17-$EA17)/ABS($EA17)) / ($EO17/$EN17-1) -> 2.6104847 | EW17: =IF(EC17<>0,((EC17-$EA17)/ABS($EA17)) / ($EO17/$EN17-1),0) -> 0.99876708 | EY17: =EV17-W17 -> 0.21001711 | EZ17: =(1-FA17)*100 -> 0 | FA17: 1 | FB17: - | FC17: - | FD17: - | FE17: - | FF17: - | FG17: - | FH17: - | FI17: -
B18: 7 | C18: 3.100813e+09 | D18: 3.1677522e+09 | E18: 3.1318189e+09 | F18: 3.1368552e+09 | G18: 3.1349101e+09 | H18: 3.1332674e+09 | K18: - | L18: - | M18: - | N18: - | O18: =C18/C$22*100 -> 8.8340671 | P18: 2.8139029e+10 | Q18: 2.842042e+10 | R18: =(Q18/P18-1)*100 -> 1.0000026 | S18: - | T18: - | U18: - | V18: - | W18: =IF(D18<>0,((D18-$C18)/ABS($C18)) / ($Q18/$P18-1),0) -> 2.1587569 | X18: =IF(E18<>0,((E18-$C18)/ABS($C18)) / ($Q18/$P18-1),0) -> 0.99992322 | Y18: =IF(F18<>0,MAX(((F18-$C18)/ABS($C18)) / ($Q18/$P18-1),0),0) -> 1.1623434 | Z18: =IF(G18<>0,MAX(((G18-$C18)/ABS($C18)) / ($Q18/$P18-1),0),0) -> 1.0996146 | AA18: =IF(H18<>0,MAX(((H18-$C18)/ABS($C18)) / ($Q18/$P18-1),0),0) -> 1.0466367 | AB18: =IF(I18<>0,MAX(((I18-$C18)/ABS($C18)) / ($Q18/$P18-1),0),AA18) -> 1.0466367 | AC18: =IF(J18<>0,MAX(((J18-$C18)/ABS($C18)) / ($Q18/$P18-1),0),AB18) -> 1.0466367 | AD18: - | AE18: - | AF18: - | AG18: - | AH18: =MIN(W18,1) -> 1 | AI18: =IF(W18>1,MAX(W18-SUM(AH18,AJ18:AO18),0),0) -> 4.4408921e-16 | AJ18: =IF(W18>1,MIN($W18-Y18,W18-AH18),0) -> 0.99641346 | AK18: =IF(W18>1,MAX(MIN(Y18-Z18,W18-AH18-AJ18),0),0) -> 0.062728784 | AL18: =IF(W18>1,MAX(MIN(Z18-AA18,W18-AH18-AJ18-AK18),0),0) -> 0.052977961 | AM18: =IF(I18<>0,IF(W18>1,MAX(MIN(AA18-AB18,W18-AH18-AJ18-AK18-AL18),0),0),0) -> 0 | AN18: =IF(J18<>0,IF(W18>1,MAX(MIN(AB18-AC18,W18-AH18-AJ18-AK18-AL18-AM18),0),0),0) -> 0 | AO18: =IF(W18>1,MAX(0,MIN(W18-AH18-AJ18-AK18-AL18-AM18,W18-AH18-AJ18-AK18-AL18-AM18-X18+1)),0) -> 0.046636679 | AP18: =AI18+AO18 -> 0.046636679 | AQ18: - | AR18: =AI18/($W18-1)*100 -> 3.8324623e-14 | AS18: =AJ18/($W18-1)*100 -> 85.989863 | AT18: =AK18/($W18-1)*100 -> 5.4134551 | AU18: =AL18/($W18-1)*100 -> 4.5719652 | AV18: =AM18/($W18-1)*100 -> 0 | AW18: =AN18/($W18-1)*100 -> 0 | AX18: =AO18/($W18-1)*100 -> 4.0247165 | AY18: =AP18/($W18-1)*100 -> 4.0247165 | AZ18: - | BA18: - | BB18: - | BC18: - | BD18: - | BE18: - | BF18: - | BG18: - | BH18: 1.8210682e+10 | BI18: 7.8274543e+09 | BJ18: 1.722736e+09 | BK18: 3.7816061e+08 | BL18: =BH18/SUM($BH18:$BK18) -> 0.64716801 | BM18: =BI18/SUM($BH18:$BK18) -> 0.2781707 | BN18: =BJ18/SUM($BH18:$BK18) -> 0.06122229 | BO18: =BK18/SUM($BH18:$BK18) -> 0.013439005 | BP18: - | BQ18: - | BR18: - | BS18: =P18/P$22*100 -> 10.737763 | CC18: - | CD18: - | CE18: - | CF18: - | CG18: - | CH18: - | CI18: - | CK18: - | CL18: - | CM18: - | CN18: - | CO18: - | CP18: - | CQ18: - | CS18: - | CT18: - | CU18: - | CV18: - | CW18: - | CX18: - | CY18: - | DA18: - | DB18: - | DC18: - | DD18: =(1-DE18)*100 -> 0 | DE18: 1 | EA18: 3.3451474e+09 | EB18: 3.4238435e+09 | EC18: 3.3785449e+09 | ED18: 3.387263e+09 | EE18: 3.3845582e+09 | EF18: 3.3827066e+09 | EG18: 3.3970863e+09 | EI18: - | EJ18: - | EK18: - | EL18: - | EM18: =EA18/EA$22*100 -> 8.5079187 | EN18: 3.2873385e+10 | EO18: 3.3202118e+10 | EP18: =(EO18/EN18-1)*100 -> 0.99999799 | EQ18: - | ER18: - | ES18: - | ET18: - | EU18: =EN18/EN$22*100 -> 10.714921 | EV18: =((EB18-$EA18)/ABS($EA18)) / ($EO18/$EN18-1) -> 2.3525494 | EW18: =IF(EC18<>0,((EC18-$EA18)/ABS($EA18)) / ($EO18/$EN18-1),0) -> 0.99838596 | EY18: =EV18-W18 -> 0.1937925 | EZ18: =(1-FA18)*100 -> 0 | FA18: 1 | FB18: - | FC18: - | FD18: - | FE18: - | FF18: - | FG18: - | FH18: - | FI18: -
B19: 8 | C19: 4.1011487e+09 | D19: 4.1833436e+09 | E19: 4.1421573e+09 | F19: 4.1473937e+09 | G19: 4.1454889e+09 | H19: 4.1434211e+09 | K19: - | L19: - | M19: - | N19: - | O19: =C19/C$22*100 -> 11.683975 | P19: 3.3005546e+10 | Q19: 3.3335601e+10 | R19: =(Q19/P19-1)*100 -> 0.9999993 | S19: - | T19: - | U19: - | V19: - | W19: =IF(D19<>0,((D19-$C19)/ABS($C19)) / ($Q19/$P19-1),0) -> 2.0041936 | X19: =IF(E19<>0,((E19-$C19)/ABS($C19)) / ($Q19/$P19-1),0) -> 0.9999289 | Y19: =IF(F19<>0,MAX(((F19-$C19)/ABS($C19)) / ($Q19/$P19-1),0),0) -> 1.1276118 | Z19: =IF(G19<>0,MAX(((G19-$C19)/ABS($C19)) / ($Q19/$P19-1),0),0) -> 1.0811655 | AA19: =IF(H19<>0,MAX(((H19-$C19)/ABS($C19)) / ($Q19/$P19-1),0),0) -> 1.0307446 | AB19: =IF(I19<>0,MAX(((I19-$C19)/ABS($C19)) / ($Q19/$P19-1),0),AA19) -> 1.0307446 | AC19: =IF(J19<>0,MAX(((J19-$C19)/ABS($C19)) / ($Q19/$P19-1),0),AB19) -> 1.0307446 | AD19: - | AE19: - | AF19: - | AG19: - | AH19: =MIN(W19,1) -> 1 | AI19: =IF(W19>1,MAX(W19-SUM(AH19,AJ19:AO19),0),0) -> 0 | AJ19: =IF(W19>1,MIN($W19-Y19,W19-AH19),0) -> 0.87658178 | AK19: =IF(W19>1,MAX(MIN(Y19-Z19,W19-AH19-AJ19),0),0) -> 0.04644632 | AL19: =IF(W19>1,MAX(MIN(Z19-AA19,W19-AH19-AJ19-AK19),0),0) -> 0.050420902 | AM19: =IF(I19<>0,IF(W19>1,MAX(MIN(AA19-AB19,W19-AH19-AJ19-AK19-AL19),0),0),0) -> 0 | AN19: =IF(J19<>0,IF(W19>1,MAX(MIN(AB19-AC19,W19-AH19-AJ19-AK19-AL19-AM19),0),0),0) -> 0 | AO19: =IF(W19>1,MAX(0,MIN(W19-AH19-AJ19-AK19-AL19-AM19,W19-AH19-AJ19-AK19-AL19-AM19-X19+1)),0) -> 0.030744593 | AP19: =AI19+AO19 -> 0.030744593 | AQ19: - | AR19: =AI19/($W19-1)*100 -> 0 | AS19: =AJ19/($W19-1)*100 -> 87.29211 | AT19: =AK19/($W19-1)*100 -> 4.6252357 | AU19: =AL19/($W19-1)*100 -> 5.0210341 | AV19: =AM19/($W19-1)*100 -> 0 | AW19: =AN19/($W19-1)*100 -> 0 | AX19: =AO19/($W19-1)*100 -> 3.0616201 | AY19: =AP19/($W19-1)*100 -> 3.0616201 | AZ19: - | BA19: - | BB19: - | BC19: - | BD19: - | BE19: - | BF19: - | BG19: - | BH19: 2.460014e+10 | BI19: 6.4777857e+09 | BJ19: 1.5379073e+09 | BK19: 3.8971272e+08 | BL19: =BH19/SUM($BH19:$BK19) -> 0.74533353 | BM19: =BI19/SUM($BH19:$BK19) -> 0.19626355 | BN19: =BJ19/SUM($BH19:$BK19) -> 0.046595423 | BO19: =BK19/SUM($BH19:$BK19) -> 0.011807492 | BP19: - | BQ19: - | BR19: - | BS19: =P19/P$22*100 -> 12.59481 | CC19: - | CD19: - | CE19: - | CF19: - | CG19: - | CH19: - | CI19: - | CK19: - | CL19: - | CM19: - | CN19: - | CO19: - | CP19: - | CQ19: - | CS19: - | CT19: - | CU19: - | CV19: - | CW19: - | CX19: - | CY19: - | DA19: - | DB19: - | DC19: - | DD19: =(1-DE19)*100 -> 0 | DE19: 1 | EA19: 4.5523314e+09 | EB19: 4.6495836e+09 | EC19: 4.5978356e+09 | ED19: 4.6064502e+09 | EE19: 4.6039233e+09 | EF19: 4.6016928e+09 | EG19: 4.624055e+09 | EI19: - | EJ19: - | EK19: - | EL19: - | EM19: =EA19/EA$22*100 -> 11.578224 | EN19: 3.8599376e+10 | EO19: 3.898537e+10 | EP19: =(EO19/EN19-1)*100 -> 1.0000005 | EQ19: - | ER19: - | ES19: - | ET19: - | EU19: =EN19/EN$22*100 -> 12.58128 | EV19: =((EB19-$EA19)/ABS($EA19)) / ($EO19/$EN19-1) -> 2.1363142 | EW19: =IF(EC19<>0,((EC19-$EA19)/ABS($EA19)) / ($EO19/$EN19-1),0) -> 0.99957932 | EY19: =EV19-W19 -> 0.13212061 | EZ19: =(1-FA19)*100 -> 0 | FA19: 1 | FB19: - | FC19: - | FD19: - | FE19: - | FF19: - | FG19: - | FH19: - | FI19: -
B20: 9 | C20: 6.4523723e+09 | D20: 6.5656336e+09 | E20: 6.5168966e+09 | F20: 6.5218994e+09 | G20: 6.5204054e+09 | H20: 6.5182733e+09 | K20: - | L20: - | M20: - | N20: - | O20: =C20/C$22*100 -> 18.382498 | P20: 4.1649731e+10 | Q20: 4.2066227e+10 | R20: =(Q20/P20-1)*100 -> 0.99999696 | S20: - | T20: - | U20: - | V20: - | W20: =IF(D20<>0,((D20-$C20)/ABS($C20)) / ($Q20/$P20-1),0) -> 1.7553482 | X20: =IF(E20<>0,((E20-$C20)/ABS($C20)) / ($Q20/$P20-1),0) -> 1.0000126 | Y20: =IF(F20<>0,MAX(((F20-$C20)/ABS($C20)) / ($Q20/$P20-1),0),0) -> 1.0775471 | Z20: =IF(G20<>0,MAX(((G20-$C20)/ABS($C20)) / ($Q20/$P20-1),0),0) -> 1.0543929 | AA20: =IF(H20<>0,MAX(((H20-$C20)/ABS($C20)) / ($Q20/$P20-1),0),0) -> 1.0213488 | AB20: =IF(I20<>0,MAX(((I20-$C20)/ABS($C20)) / ($Q20/$P20-1),0),AA20) -> 1.0213488 | AC20: =IF(J20<>0,MAX(((J20-$C20)/ABS($C20)) / ($Q20/$P20-1),0),AB20) -> 1.0213488 | AD20: - | AE20: - | AF20: - | AG20: - | AH20: =MIN(W20,1) -> 1 | AI20: =IF(W20>1,MAX(W20-SUM(AH20,AJ20:AO20),0),0) -> 1.2626763e-05 | AJ20: =IF(W20>1,MIN($W20-Y20,W20-AH20),0) -> 0.67780111 | AK20: =IF(W20>1,MAX(MIN(Y20-Z20,W20-AH20-AJ20),0),0) -> 0.023154205 | AL20: =IF(W20>1,MAX(MIN(Z20-AA20,W20-AH20-AJ20-AK20),0),0) -> 0.033044062 | AM20: =IF(I20<>0,IF(W20>1,MAX(MIN(AA20-AB20,W20-AH20-AJ20-AK20-AL20),0),0),0) -> 0 | AN20: =IF(J20<>0,IF(W20>1,MAX(MIN(AB20-AC20,W20-AH20-AJ20-AK20-AL20-AM20),0),0),0) -> 0 | AO20: =IF(W20>1,MAX(0,MIN(W20-AH20-AJ20-AK20-AL20-AM20,W20-AH20-AJ20-AK20-AL20-AM20-X20+1)),0) -> 0.021336167 | AP20: =AI20+AO20 -> 0.021348794 | AQ20: - | AR20: =AI20/($W20-1)*100 -> 0.001671648 | AS20: =AJ20/($W20-1)*100 -> 89.7336 | AT20: =AK20/($W20-1)*100 -> 3.0653685 | AU20: =AL20/($W20-1)*100 -> 4.3746796 | AV20: =AM20/($W20-1)*100 -> 0 | AW20: =AN20/($W20-1)*100 -> 0 | AX20: =AO20/($W20-1)*100 -> 2.8246798 | AY20: =AP20/($W20-1)*100 -> 2.8263515 | AZ20: - | BA20: - | BB20: - | BC20: - | BD20: - | BE20: - | BF20: - | BG20: - | BH20: 2.8983696e+10 | BI20: 8.3325448e+09 | BJ20: 3.0093877e+09 | BK20: 1.3241043e+09 | BL20: =BH20/SUM($BH20:$BK20) -> 0.69589152 | BM20: =BI20/SUM($BH20:$BK20) -> 0.20006239 | BN20: =BJ20/SUM($BH20:$BK20) -> 0.072254672 | BO20: =BK20/SUM($BH20:$BK20) -> 0.031791423 | BP20: - | BQ20: - | BR20: - | BS20: =P20/P$22*100 -> 15.893404 | CC20: - | CD20: - | CE20: - | CF20: - | CG20: - | CH20: - | CI20: - | CK20: - | CL20: - | CM20: - | CN20: - | CO20: - | CP20: - | CQ20: - | CS20: - | CT20: - | CU20: - | CV20: - | CW20: - | CX20: - | CY20: - | DA20: - | DB20: - | DC20: - | DD20: =(1-DE20)*100 -> 0 | DE20: 1 | EA20: 7.3342782e+09 | EB20: 7.4667905e+09 | EC20: 7.407532e+09 | ED20: 7.4150022e+09 | EE20: 7.4128918e+09 | EF20: 7.4106277e+09 | EG20: 7.4240684e+09 | EI20: - | EJ20: - | EK20: - | EL20: - | EM20: =EA20/EA$22*100 -> 18.65372 | EN20: 4.8567602e+10 | EO20: 4.9053279e+10 | EP20: =(EO20/EN20-1)*100 -> 1.0000018 | EQ20: - | ER20: - | ES20: - | ET20: - | EU20: =EN20/EN$22*100 -> 15.830375 | EV20: =((EB20-$EA20)/ABS($EA20)) / ($EO20/$EN20-1) -> 1.8067495 | EW20: =IF(EC20<>0,((EC20-$EA20)/ABS($EA20)) / ($EO20/$EN20-1),0) -> 0.99878541 | EY20: =EV20-W20 -> 0.051401334 | EZ20: =(1-FA20)*100 -> 0 | FA20: 1 | FB20: - | FC20: - | FD20: - | FE20: - | FF20: - | FG20: - | FH20: - | FI20: -
B21: 10 | C21: 1.6084719e+10 | D21: 1.6310707e+10 | E21: 1.6245567e+10 | F21: 1.625108e+10 | G21: 1.624988e+10 | H21: 1.6247567e+10 | K21: - | L21: - | M21: - | N21: - | O21: =C21/C$22*100 -> 45.824591 | P21: 6.9987948e+10 | Q21: 7.0687826e+10 | R21: =(Q21/P21-1)*100 -> 0.99999713 | S21: - | T21: - | U21: - | V21: - | W21: =IF(D21<>0,((D21-$C21)/ABS($C21)) / ($Q21/$P21-1),0) -> 1.4049842 | X21: =IF(E21<>0,((E21-$C21)/ABS($C21)) / ($Q21/$P21-1),0) -> 1.0000029 | Y21: =IF(F21<>0,MAX(((F21-$C21)/ABS($C21)) / ($Q21/$P21-1),0),0) -> 1.0342826 | Z21: =IF(G21<>0,MAX(((G21-$C21)/ABS($C21)) / ($Q21/$P21-1),0),0) -> 1.026818 | AA21: =IF(H21<>0,MAX(((H21-$C21)/ABS($C21)) / ($Q21/$P21-1),0),0) -> 1.012439 | AB21: =IF(I21<>0,MAX(((I21-$C21)/ABS($C21)) / ($Q21/$P21-1),0),AA21) -> 1.012439 | AC21: =IF(J21<>0,MAX(((J21-$C21)/ABS($C21)) / ($Q21/$P21-1),0),AB21) -> 1.012439 | AD21: - | AE21: - | AF21: - | AG21: - | AH21: =MIN(W21,1) -> 1 | AI21: =IF(W21>1,MAX(W21-SUM(AH21,AJ21:AO21),0),0) -> 2.9127634e-06 | AJ21: =IF(W21>1,MIN($W21-Y21,W21-AH21),0) -> 0.37070161 | AK21: =IF(W21>1,MAX(MIN(Y21-Z21,W21-AH21-AJ21),0),0) -> 0.0074645984 | AL21: =IF(W21>1,MAX(MIN(Z21-AA21,W21-AH21-AJ21-AK21),0),0) -> 0.014378954 | AM21: =IF(I21<>0,IF(W21>1,MAX(MIN(AA21-AB21,W21-AH21-AJ21-AK21-AL21),0),0),0) -> 0 | AN21: =IF(J21<>0,IF(W21>1,MAX(MIN(AB21-AC21,W21-AH21-AJ21-AK21-AL21-AM21),0),0),0) -> 0 | AO21: =IF(W21>1,MAX(0,MIN(W21-AH21-AJ21-AK21-AL21-AM21,W21-AH21-AJ21-AK21-AL21-AM21-X21+1)),0) -> 0.012436105 | AP21: =AI21+AO21 -> 0.012439018 | AQ21: - | AR21: =AI21/($W21-1)*100 -> 0.00071922894 | AS21: =AJ21/($W21-1)*100 -> 91.534837 | AT21: =AK21/($W21-1)*100 -> 1.8431827 | AU21: =AL21/($W21-1)*100 -> 3.5504976 | AV21: =AM21/($W21-1)*100 -> 0 | AW21: =AN21/($W21-1)*100 -> 0 | AX21: =AO21/($W21-1)*100 -> 3.0707631 | AY21: =AP21/($W21-1)*100 -> 3.0714823 | AZ21: - | BA21: - | BB21: - | BC21: - | BD21: - | BE21: - | BF21: - | BG21: - | BH21: 4.7316502e+10 | BI21: 9.5777991e+09 | BJ21: 9.5558316e+09 | BK21: 3.5378168e+09 | BL21: =BH21/SUM($BH21:$BK21) -> 0.67606641 | BM21: =BI21/SUM($BH21:$BK21) -> 0.13684926 | BN21: =BJ21/SUM($BH21:$BK21) -> 0.13653539 | BO21: =BK21/SUM($BH21:$BK21) -> 0.050548942 | BP21: - | BQ21: - | BR21: - | BS21: =P21/P$22*100 -> 26.707177 | CC21: - | CD21: - | CE21: - | CF21: - | CG21: - | CH21: - | CI21: - | CK21: - | CL21: - | CM21: - | CN21: - | CO21: - | CP21: - | CQ21: - | CS21: - | CT21: - | CU21: - | CV21: - | CW21: - | CX21: - | CY21: - | DA21: - | DB21: - | DC21: - | DD21: =(1-DE21)*100 -> 0 | DE21: 1 | EA21: 1.9008203e+10 | EB21: 1.9278713e+10 | EC21: 1.9198265e+10 | ED21: 1.9205481e+10 | EE21: 1.9203853e+10 | EF21: 1.9201379e+10 | EG21: 1.9183808e+10 | EI21: - | EJ21: - | EK21: - | EL21: - | EM21: =EA21/EA$22*100 -> 48.344729 | EN21: 8.2248813e+10 | EO21: 8.3071304e+10 | EP21: =(EO21/EN21-1)*100 -> 1.0000026 | EQ21: - | ER21: - | ES21: - | ET21: - | EU21: =EN21/EN$22*100 -> 26.808603 | EV21: =((EB21-$EA21)/ABS($EA21)) / ($EO21/$EN21-1) -> 1.4231201 | EW21: =IF(EC21<>0,((EC21-$EA21)/ABS($EA21)) / ($EO21/$EN21-1),0) -> 0.99989073 | EY21: =EV21-W21 -> 0.018135883 | EZ21: =(1-FA21)*100 -> 0 | FA21: 1 | FB21: - | FC21: - | FD21: - | FE21: - | FF21: - | FG21: - | FH21: - | FI21: -
B22: Total | C22: 3.5100628e+10 | D22: 3.5762845e+10 | E22: 3.5451607e+10 | F22: 3.5500465e+10 | G22: 3.5482469e+10 | H22: 3.5469232e+10 | K22: {='[2]2. Distributional by deciles o'!$H$92:$K$92} -> 3.5516722e+10 | L22: 3.5259487e+10 | M22: 3.5169067e+10 | N22: 3.5120056e+10 | O22: - | P22: 2.6205671e+11 | Q22: 2.6467727e+11 | R22: =(Q22/P22-1)*100 -> 0.99999883 | S22: {='[2]2. Distributional by deciles o'!$H$110:$K$110} -> 2.6376118e+11 | T22: 2.6269008e+11 | U22: 2.6226894e+11 | V22: 2.621272e+11 | W22: =IF(D22<>0,((D22-$C22)/ABS($C22)) / ($Q22/$P22-1),0) -> 1.8866256 | X22: =IF(E22<>0,((E22-$C22)/ABS($C22)) / ($Q22/$P22-1),0) -> 0.99992341 | Y22: =IF(F22<>0,MAX(((F22-$C22)/ABS($C22)) / ($Q22/$P22-1),0),0) -> 1.1391169 | Z22: =IF(G22<>0,MAX(((G22-$C22)/ABS($C22)) / ($Q22/$P22-1),0),0) -> 1.0878457 | AA22: =IF(H22<>0,MAX(((H22-$C22)/ABS($C22)) / ($Q22/$P22-1),0),0) -> 1.0501338 | AB22: =IF(I22<>0,MAX(((I22-$C22)/ABS($C22)) / ($Q22/$P22-1),0),AA22) -> 1.0501338 | AC22: =IF(J22<>0,MAX(((J22-$C22)/ABS($C22)) / ($Q22/$P22-1),0),AB22) -> 1.0501338 | AD22: =(K22/$C22-1) / (S22/$P22-1) -> 1.8225672 | AE22: =(L22/$C22-1) / (T22/$P22-1) -> 1.8725384 | AF22: =(M22/$C22-1) / (U22/$P22-1) -> 2.4075526 | AG22: =(N22/$C22-1) / (V22/$P22-1) -> 2.057656 | AH22: =MIN(W22,1) -> 1 | AI22: =IF(W22>1,MAX(W22-SUM(AH22,AJ22:AO22),0),0) -> 0 | AJ22: =IF(W22>1,MIN($W22-Y22,W22-AH22),0) -> 0.74750879 | AK22: =IF(W22>1,MAX(MIN(Y22-Z22,W22-AH22-AJ22),0),0) -> 0.051271133 | AL22: =IF(W22>1,MAX(MIN(Z22-AA22,W22-AH22-AJ22-AK22),0),0) -> 0.037711883 | AM22: =IF(I22<>0,IF(W22>1,MAX(MIN(AA22-AB22,W22-AH22-AJ22-AK22-AL22),0),0),0) -> 0 | AN22: =IF(J22<>0,IF(W22>1,MAX(MIN(AB22-AC22,W22-AH22-AJ22-AK22-AL22-AM22),0),0),0) -> 0 | AO22: =IF(W22>1,MAX(0,MIN(W22-AH22-AJ22-AK22-AL22-AM22,W22-AH22-AJ22-AK22-AL22-AM22-X22+1)),0) -> 0.050133834 | AP22: =AI22+AO22 -> 0.050133834 | AQ22: - | AR22: =AI22/($W22-1)*100 -> 0 | AS22: =AJ22/($W22-1)*100 -> 84.309404 | AT22: =AK22/($W22-1)*100 -> 5.7827262 | AU22: =AL22/($W22-1)*100 -> 4.2534167 | AV22: =AM22/($W22-1)*100 -> 0 | AW22: =AN22/($W22-1)*100 -> 0 | AX22: =AO22/($W22-1)*100 -> 5.6544534 | AY22: =AP22/($W22-1)*100 -> 5.6544534 | AZ22: 1.97 | BA22: 2 | BB22: 1.85 | BC22: 1.7 | BD22: =W22-AZ22 -> -0.083374358 | BE22: =AD22-BA22 -> -0.17743284 | BF22: =AF22-BB22 -> 0.55755258 | BG22: =AG22-BC22 -> 0.35765597 | BH22: 1.7044656e+11 | BI22: 6.3337627e+10 | BJ22: 2.1222924e+10 | BK22: 7.0496094e+09 | BL22: =BH22/SUM($BH22:$BK22) -> 0.65041858 | BM22: =BI22/SUM($BH22:$BK22) -> 0.24169435 | BN22: =BJ22/SUM($BH22:$BK22) -> 0.080985994 | BO22: =BK22/SUM($BH22:$BK22) -> 0.026901082 | BP22: =(AD22*BL22+AF22*BN22+AG22*BO22)/(BL22+BN22+BO22) -> 1.8933826 | BQ22: =W22-BP22 -> -0.0067569829 | BR22: =BP22-AZ22 -> -0.076617375 | BS22: - | CK22: ='[2]3. Inequality and Poverty'!$B$7 -> 0.35867389 | CL22: ='[2]3. Inequality and Poverty'!$B$8 -> 0.31858803 | CM22: ='[2]3. Inequality and Poverty'!$C$7 -> 0.35867389 | CN22: ='[2]3. Inequality and Poverty'!$C$8 -> 0.3186097 | CO22: =(CK22-CL22)/CK22 -> 0.11176132 | CP22: =(CM22-CN22)/CM22 -> 0.11170087 | CQ22: =(CP22-CO22)*100 -> -0.0060455769 | CR22: =CN22-CL22 -> 2.1676367e-05 | CS22: =(SUM(P20:P21))/(SUM(P12:P13)) -> 8.210018 | CT22: =(SUM(P20:P21)-SUM(C20:C21))/(SUM(P12:P13)-SUM(C12:C13)) -> 6.4902685 | CU22: =(SUM(Q20:Q21))/(SUM(Q12:Q13)) -> 8.2100175 | CV22: =(SUM(Q20:Q21)-SUM(D20:D21))/(SUM(Q12:Q13)-SUM(D12:D13)) -> 6.4879274 | CW22: =(CS22-CT22)/CS22 -> 0.20946964 | CX22: =(CU22-CV22)/CU22 -> 0.20975474 | CY22: =(CX22-CW22)*100 -> 0.028510268 | CZ22: =CV22-CT22 -> -0.0023410741 | DA22: {='[2]3. Inequality and Poverty'!$B$34:$C$34} -> 0.2704958 | DB22: 0.26756475 | DC22: =DB22-DA22 -> -0.0029310443 | DD22: =(1-DE22)*100 -> 3.3936931 | DE22: 0.96606307 | EA22: 3.9318046e+10 | EB22: 4.0100437e+10 | EC22: 3.9710974e+10 | ED22: 3.9792865e+10 | EE22: 3.9768688e+10 | EF22: 3.974321e+10 | EG22: 3.981954e+10 | EI22: {='[3]2. Distributional by deciles o'!$H$92:$K$92} -> 3.981954e+10 | EJ22: 3.9495375e+10 | EK22: 3.9399905e+10 | EL22: 3.9340776e+10 | EM22: - | EN22: 3.0680007e+11 | EO22: 3.0986808e+11 | EP22: =(EO22/EN22-1)*100 -> 0.99999999 | EQ22: {='[3]2. Distributional by deciles o'!$H$110:$K$110} -> 3.0882076e+11 | ER22: 3.0751423e+11 | ES22: 3.0705442e+11 | ET22: 3.0687889e+11 | EU22: - | EV22: =((EB22-$EA22)/ABS($EA22)) / ($EO22/$EN22-1) -> 1.9899028 | EW22: =IF(EC22<>0,((EC22-$EA22)/ABS($EA22)) / ($EO22/$EN22-1),0) -> 0.9993561 | EX22: =EW22-X22 -> -0.00056730899 | EY22: =EV22-W22 -> 0.10327713 | EZ22: =(1-FA22)*100 -> 1.6546433 | FA22: 0.98345357 | FB22: =(EI22/$EA22-1) / (EQ22/$EN22-1) -> 1.9365548 | FC22: =(EJ22/$EA22-1) / (ER22/$EN22-1) -> 1.9375453 | FD22: =(EK22/$EA22-1) / (ES22/$EN22-1) -> 2.5113079 | FE22: =(EL22/$EA22-1) / (ET22/$EN22-1) -> 2.2504535 | FF22: =FB22-AD22 -> 0.11398765 | FG22: =FC22-AE22 -> 0.065006953 | FH22: =FD22-AF22 -> 0.10375537 | FI22: =FE22-AG22 -> 0.19279756

Sheet 2AT
B2: Template corresponding to Part 2 of the project Fiscal Drag in Europe.
B3: Yellow cells have to be filled by you
B4: Remaing cells are automatically calculated using information from yellow cells (grey cells remain empty)
B5: Red cells are 2026 results that can be filled with fake/provisional results. When we fill them with final results (the plan is to use Dec BMPE data) turn them yellow.
B8: Country | C8: AT | D8: Austria | E8: Updated: dd/mm/2025
C10: Personal Income Tax Revenue | P10: Tax Base (il_fiscaldrag_all) | AM10: Sensitivity test
B11: Decile | C11: 2019_baseline | D11: 2020_baseline | E11: 2021_baseline | F11: 2022_baseline | G11: 2023_baseline | H11: 2023 if 2019legis unchanged (upper bound) | I11: 2023 if 2019legis indexed with tax base growth (lower bound a) | J11: 2023 if 2019legis indexed with lagged HCPI (lower bound b) | K11: 2023 if 2019legis indexed with concurrent HCPI (lower bound c) | P11: 2019_baseline | Q11: 2020_baseline | R11: 2021_baseline | S11: 2022_baseline | T11: 2023_baseline | U11: Growth rate 2023/2019 | AK11: 2023_baseline without indexation measures | AM11: TBB elasticity | AN11: 2023_newbaseline | AO11: 2023_homogeneous | AP11: 2023_heterogeneous | AQ11: initial growth | AR11: adjusted growth | AS11: weight
B12: 1 | C12: {='[4]2. Distributional by deciles o'!$B$82:$F$92} -> -1.5702069e+08 | D12: -2.0794697e+08 | E12: -2.3632036e+08 | F12: -3.3914978e+08 | G12: -2.9724656e+08 | H12: {='[4]2. Distributional by deciles o'!$H$82:$K$92} -> -1.3626453e+08 | I12: -1.7717673e+08 | J12: -1.7568175e+08 | K12: -1.9361364e+08 | P12: {='[4]2. Distributional by deciles o'!$B$100:$F$110} -> 3.2257884e+09 | Q12: 3.2881219e+09 | R12: 3.3803686e+09 | S12: 3.5231959e+09 | T12: 3.768538e+09 | U12: =T12/P12-1 -> 0.16825332 | AK12: {='[4]2. Distributional by deciles o'!$L$82:$L$92} -> -2.6743198e+08 | AM12: {=INDIRECT("'1"&$C$8&"'!W12")} -> 0.55434579 | AN12: =C12+C12*U12*AM12 -> -1.7166609e+08 | AO12: =C12+C12*U$22*AM12 -> -1.7188247e+08 | AP12: =C12+C12*AR12*AM12 -> -1.7166609e+08 | AQ12: =U12 -> 0.16825332 | AR12: =AQ12 -> 0.16825332 | AS12: =P12/P$22 -> 0.012309505
B13: 2 | C13: 26423258 | D13: -1.1352545e+08 | E13: -1.7300794e+08 | F13: -2.6472351e+08 | G13: -1.76391e+08 | H13: 2.4328725e+08 | I13: 39735715 | J13: 45953963 | K13: -18906640 | P13: 1.037195e+10 | Q13: 1.0610427e+10 | R13: 1.0911393e+10 | S13: 1.1325073e+10 | T13: 1.2110872e+10 | U13: =T13/P13-1 -> 0.16765619 | AK13: 4137109.8 | AM13: {=INDIRECT("'1"&$C$8&"'!W13")} -> 39.258922 | AN13: =C13+C13*U13*AM13 -> 2.0034118e+08 | AO13: =C13+C13*U$22*AM13 -> 2.0353938e+08 | AP13: =C13+C13*AR13*AM13 -> 2.0034118e+08 | AQ13: =U13 -> 0.16765619 | AR13: =AQ13 -> 0.16765619 | AS13: =P13/P$22 -> 0.039579029
B14: 3 | C14: 5.3322438e+08 | D14: 3.8025507e+08 | E14: 3.8231386e+08 | F14: 2.7634964e+08 | G14: 3.8361334e+08 | H14: 9.8775242e+08 | I14: 6.4008163e+08 | J14: 6.5249807e+08 | K14: 5.1250314e+08 | P14: 1.4137687e+10 | Q14: 1.4432777e+10 | R14: 1.4803798e+10 | S14: 1.5376819e+10 | T14: 1.6467652e+10 | U14: =T14/P14-1 -> 0.16480527 | AK14: 5.6554547e+08 | AM14: {=INDIRECT("'1"&$C$8&"'!W14")} -> 4.8325244 | AN14: =C14+C14*U14*AM14 -> 9.5789785e+08 | AO14: =C14+C14*U$22*AM14 -> 9.7318864e+08 | AP14: =C14+C14*AR14*AM14 -> 9.5789785e+08 | AQ14: =U14 -> 0.16480527 | AR14: =AQ14 -> 0.16480527 | AS14: =P14/P$22 -> 0.053948959
B15: 4 | C15: 1.0527935e+09 | D15: 9.0090455e+08 | E15: 9.5119044e+08 | F15: 8.6863887e+08 | G15: 9.8829801e+08 | H15: 1.6778239e+09 | I15: 1.24448e+09 | J15: 1.2605063e+09 | K15: 1.0810566e+09 | P15: 1.7268543e+10 | Q15: 1.76215e+10 | R15: 1.8086398e+10 | S15: 1.8797211e+10 | T15: 2.0112856e+10 | U15: =T15/P15-1 -> 0.1647107 | AK15: 1.1906189e+09 | AM15: {=INDIRECT("'1"&$C$8&"'!W15")} -> 3.4818014 | AN15: =C15+C15*U15*AM15 -> 1.65656e+09 | AO15: =C15+C15*U$22*AM15 -> 1.6786584e+09 | AP15: =C15+C15*AR15*AM15 -> 1.65656e+09 | AQ15: =U15 -> 0.1647107 | AR15: =AQ15 -> 0.1647107 | AS15: =P15/P$22 -> 0.065896205
B16: 5 | C16: 1.6073541e+09 | D16: 1.4711325e+09 | E16: 1.5660649e+09 | F16: 1.5104053e+09 | G16: 1.6428539e+09 | H16: 2.3800382e+09 | I16: 1.9036162e+09 | J16: 1.92139e+09 | K16: 1.7199437e+09 | P16: 2.0486801e+10 | Q16: 2.0893159e+10 | R16: 2.1460044e+10 | S16: 2.2332654e+10 | T16: 2.3911846e+10 | U16: =T16/P16-1 -> 0.16718297 | AK16: 1.8374689e+09 | AM16: {=INDIRECT("'1"&$C$8&"'!W16")} -> 2.7986468 | AN16: =C16+C16*U16*AM16 -> 2.3594127e+09 | AO16: =C16+C16*U$22*AM16 -> 2.3754103e+09 | AP16: =C16+C16*AR16*AM16 -> 2.3594127e+09 | AQ16: =U16 -> 0.16718297 | AR16: =AQ16 -> 0.16718297 | AS16: =P16/P$22 -> 0.078176977
B17: 6 | C17: 2.2988003e+09 | D17: 2.1687198e+09 | E17: 2.2885061e+09 | F17: 2.2600717e+09 | G17: 2.4292412e+09 | H17: 3.243044e+09 | I17: 2.7200063e+09 | J17: 2.7396981e+09 | K17: 2.5155369e+09 | P17: 2.3783687e+10 | Q17: 2.426369e+10 | R17: 2.4894753e+10 | S17: 2.5887072e+10 | T17: 2.7768145e+10 | U17: =T17/P17-1 -> 0.16752904 | AK17: 2.6375182e+09 | AM17: {=INDIRECT("'1"&$C$8&"'!W17")} -> 2.4004676 | AN17: =C17+C17*U17*AM17 -> 3.2232584e+09 | AO17: =C17+C17*U$22*AM17 -> 3.2409729e+09 | AP17: =C17+C17*AR17*AM17 -> 3.2232584e+09 | AQ17: =U17 -> 0.16752904 | AR17: =AQ17 -> 0.16752904 | AS17: =P17/P$22 -> 0.090757787
B18: 7 | C18: 3.100813e+09 | D18: 2.9777761e+09 | E18: 3.137534e+09 | F18: 3.1636513e+09 | G18: 3.3665093e+09 | H18: 4.2668275e+09 | I18: 3.6720612e+09 | J18: 3.6940184e+09 | K18: 3.4462696e+09 | P18: 2.8139029e+10 | Q18: 2.8688938e+10 | R18: 2.9461291e+10 | S18: 3.0668583e+10 | T18: 3.2880887e+10 | U18: =T18/P18-1 -> 0.16851533 | AK18: 3.6049385e+09 | AM18: {=INDIRECT("'1"&$C$8&"'!W18")} -> 2.1587569 | AN18: =C18+C18*U18*AM18 -> 4.2288381e+09 | AO18: =C18+C18*U$22*AM18 -> 4.2437247e+09 | AP18: =C18+C18*AR18*AM18 -> 4.2288381e+09 | AQ18: =U18 -> 0.16851533 | AR18: =AQ18 -> 0.16851533 | AS18: =P18/P$22 -> 0.10737763
B19: 8 | C19: 4.1011487e+09 | D19: 3.9916437e+09 | E19: 4.2075365e+09 | F19: 4.2969825e+09 | G19: 4.5875862e+09 | H19: 5.5702552e+09 | I19: 4.8925107e+09 | J19: 4.9179668e+09 | K19: 4.6305432e+09 | P19: 3.3005546e+10 | Q19: 3.3634378e+10 | R19: 3.4547014e+10 | S19: 3.6017444e+10 | T19: 3.8726234e+10 | U19: =T19/P19-1 -> 0.17332506 | AK19: 4.8342037e+09 | AM19: {=INDIRECT("'1"&$C$8&"'!W19")} -> 2.0041936 | AN19: =C19+C19*U19*AM19 -> 5.5257934e+09 | AO19: =C19+C19*U$22*AM19 -> 5.5045392e+09 | AP19: =C19+C19*AR19*AM19 -> 5.1405121e+09 | AQ19: =U19 -> 0.17332506 | AR19: =U19-AP31*AS21/SUM(AS19:AS20) -> 0.12645098 | AS19: =P19/P$22 -> 0.1259481
B20: 9 | C20: 6.4523723e+09 | D20: 6.3961503e+09 | E20: 6.7169703e+09 | F20: 6.9749345e+09 | G20: 7.3769942e+09 | H20: 8.4600046e+09 | I20: 7.6749179e+09 | J20: 7.7048948e+09 | K20: 7.364033e+09 | P20: 4.1649731e+10 | Q20: 4.2428207e+10 | R20: 4.3599841e+10 | S20: 4.5491435e+10 | T20: 4.8821129e+10 | U20: =T20/P20-1 -> 0.17218355 | AK20: 7.6565078e+09 | AM20: {=INDIRECT("'1"&$C$8&"'!W20")} -> 1.7553482 | AN20: =C20+C20*U20*AM20 -> 8.4025507e+09 | AO20: =C20+C20*U$22*AM20 -> 8.3861923e+09 | AP20: =C20+C20*AR20*AM20 -> 7.8716474e+09 | AQ20: =U20 -> 0.17218355 | AR20: =U20-AP31*AS21/SUM(AS19:AS20) -> 0.12530947 | AS20: =P20/P$22 -> 0.15893404
B21: 10 | C21: 1.6084719e+10 | D21: 1.6177745e+10 | E21: 1.6934383e+10 | F21: 1.7905816e+10 | G21: 1.9016588e+10 | H21: 2.0246351e+10 | I21: 1.9190259e+10 | J21: 1.9230433e+10 | K21: 1.8774946e+10 | P21: 6.9987948e+10 | Q21: 7.1163642e+10 | R21: 7.3332058e+10 | S21: 7.6804596e+10 | T21: 8.2231915e+10 | U21: =T21/P21-1 -> 0.17494393 | AK21: 1.9359536e+10 | AM21: {=INDIRECT("'1"&$C$8&"'!W21")} -> 1.4049842 | AN21: =C21+C21*U21*AM21 -> 2.0038238e+10 | AO21: =C21+C21*U$22*AM21 -> 1.9943217e+10 | AP21: =C21+C21*AR21*AM21 -> 2.1168177e+10 | AQ21: =U21 -> 0.17494393 | AR21: =U21+AP31 -> 0.22494393 | AS21: =P21/P$22 -> 0.26707177
B22: Total | C22: 3.5100628e+10 | D22: 3.4142855e+10 | E22: 3.5775171e+10 | F22: 3.6652976e+10 | G22: 3.9318046e+10 | H22: 4.693912e+10 | I22: 4.1800492e+10 | J22: 4.1991678e+10 | K22: 3.9832312e+10 | P22: 2.6205671e+11 | Q22: 2.6702484e+11 | R22: 2.7447696e+11 | S22: 2.8622408e+11 | T22: 3.0680007e+11 | U22: =T22/P22-1 -> 0.17073924 | AK22: 4.1423042e+10 | AM22: {=INDIRECT("'1"&$C$8&"'!W22")} -> 1.8866256 | AN22: =SUM(AN12:AN21) -> 4.6421224e+10 | AO22: =SUM(AO12:AO21) -> 4.6377561e+10 | AP22: =SUM(AP12:AP21) -> 4.6634979e+10 | AQ22: =SUMPRODUCT(AQ12:AQ21,AS12:AS21) -> 0.17073924 | AR22: =SUMPRODUCT(AR12:AR21,AS12:AS21) -> 0.17073924
AR23: =U22 -> 0.17073924
G24: inc.growth | H24: =U22 -> 0.17073924 | K24: inc.growth | AN24: =AN22/G22-1 -> 0.18065949 | AR24: =IF(AR23-AR22<0.0000000001,"ok","wrong") -> ok
G25: laggedHCPI | H25: 0.1486 | K25: laggedHCPI | AR25: =IF(AQ22-AR22<0.0000000001,"ok","wrong") -> ok
G26: concurr.HCPI | H26: 0.2189 | K26: concurr.HCPI | AM26: relative to new baseline 2023 | AO26: =AO22/$AN22-1 -> -0.00094059748 | AP26: =AP22/$AN22-1 -> 0.0046046647
AM28: relative to potential fiscal drag | AO28: =(AO22-$AN22)/($W$37*1000000) -> -0.0074007692 | AP28: =(AP22-$AN22)/($W$37*1000000) -> 0.036230228
B29: Outcome: total tax revenue
B30: Query: | C30: UPDATE FOR BMPE: Growth rate from old projections on top of NA | D30: lv; var=B1GQ:=SC_devgr101.DATA!ISIS&4575.ESVG2010&38,CAT(B1GQ; YED_AT_J*YER_AT_J;'cp'),(D51A_C01+D51A_C08)*100/B1GQ,(D51A_C01+D51A_C08)*1000000; date=8J to 2026; offset=2,-1; error=; txt=off; txt2=off; txt3=off; info=0; dateformat=off; daterangeformat=1 | AC30: Table for results (share GDP)
B31: Table for calculations | E31: For reescaling | F31: For reescaling | H31: All these are reescaled | N31: Table for results (million euros) | P31: Actual Fiscal Drag | T31: Potential Fiscal Drag | X31: Effective offsetting of Fiscal Drag | AC31: Actual Fiscal Drag | AF31: Potential Fiscal Drag | AO31: shock | AP31: 0.05
C32: Baseline (before reescaling) | D32: GDP (million euros) | E32: National Account PIT Revenue observed | F32: National Account PIT Revenue observed (euros) | G32: Reescaling factor | H32: Baseline | I32: Legislation unchanged since 2019/2023 | J32: Index with tax base growth | K32: Index with lagged HCPI | L32: Index with concurrent HCPI | M32: Baseline w/o "indexation measures" | O32: Size of reescaling | P32: Actual Fiscal Drag (wrt tax.inc.growth) | Q32: Actual Fiscal Drag (wrt lagged HCPI) | R32: Actual Fiscal Drag (wrt concurrent HCPI) | S32: Actual Fiscal Drag (wrt average index) | T32: Potential Fiscal Drag (wrt tax.inc.growth) | U32: Potential Fiscal Drag (wrt lagged HCPI) | V32: Potential Fiscal Drag (wrt concurrent HCPI) | W32: Potential Fiscal Drag (wrt average index) | X32: % Offsetting (wrt tax.inc.growth) | Y32: % Offsetting (wrt lagged HCPI) | Z32: % Offsetting (wrt concurrent HCPI) | AA32: % Offsetting (wrt average index) | AC32: Actual Fiscal Drag (wrt tax.inc.growth) | AD32: Actual Fiscal Drag (wrt lagged HCPI) | AE32: Actual Fiscal Drag (wrt concurrent HCPI) | AF32: Potential Fiscal Drag (wrt tax.inc.growth) | AG32: Potential Fiscal Drag (wrt lagged HCPI) | AH32: Potential Fiscal Drag (wrt concurrent HCPI)
B33: 2019 | C33: =C22 -> 3.5100628e+10 | D33: 395706.77 | E33: 8.9520508 | F33: 3.5423871e+10 | G33: =F33/C33 -> 1.009209 | H33: =C33*G33 -> 3.5423871e+10 | I33: - | J33: - | K33: - | L33: - | N33: 2019 | O33: =G33 -> 1.009209
B34: 2020 | C34: =D22 -> 3.4142855e+10 | D34: 380317.88 | E34: 8.6871036 | F34: 3.3038608e+10 | G34: =F34/C34 -> 0.96765806 | H34: =C34*G34 -> 3.3038608e+10 | N34: 2020
B35: 2021 | C35: =E22 -> 3.5775171e+10 | D35: 406232.06 | E35: 8.8437542 | F35: 3.5926165e+10 | G35: =F35/C35 -> 1.0042206 | H35: =C35*G35 -> 3.5926165e+10 | N35: 2021
B36: 2022 | C36: =F22 -> 3.6652976e+10 | D36: 448007.45 | E36: 8.786152 | F36: 3.9362615e+10 | G36: =F36/C36 -> 1.0739268 | H36: =C36*G36 -> 3.9362615e+10 | N36: 2022
B37: 2023 | C37: =G22 -> 3.9318046e+10 | D37: 473226.72 | E37: 8.5534027 | F37: 4.0476987e+10 | G37: =F37/C37 -> 1.029476 | H37: =C37*G37 -> 4.0476987e+10 | I37: =H22*$G37 -> 4.8322699e+10 | J37: =I22*$G37 -> 4.3032605e+10 | K37: =J22*$G37 -> 4.3229426e+10 | L37: =K22*$G37 -> 4.1006411e+10 | M37: =AK22*$G37 -> 4.264403e+10 | N37: 2023 | O37: =G37 -> 1.029476 | P37: =($H37-J37)/1000000 -> -2555.6182 | Q37: =($H37-K37)/1000000 -> -2752.4392 | R37: =($H37-L37)/1000000 -> -529.42439 | S37: =AVERAGE(P37:R37) -> -1945.8273 | T37: =($I37-J37)/1000000 -> 5290.094 | U37: =($I37-K37)/1000000 -> 5093.273 | V37: =($I37-L37)/1000000 -> 7316.2878 | W37: =AVERAGE(T37:V37) -> 5899.8849 | X37: =(T37-P37)/T37 -> 1.483095 | Y37: =(U37-Q37)/U37 -> 1.5404068 | Z37: =(V37-R37)/V37 -> 1.0723624 | AA37: =AVERAGE(X37:Z37) -> 1.3652881 | AC37: =P37/$D37 -> -0.0054004098 | AD37: =Q37/$D37 -> -0.0058163225 | AE37: =R37/$D37 -> -0.0011187542 | AF37: =T37/$D37 -> 0.011178773 | AG37: =U37/$D37 -> 0.01076286 | AH37: =V37/$D37 -> 0.015460428
B38: 2024 | D38: 493091.52 | N38: 2024
B39: 2025 | D39: 516212.47 | N39: 2025
B40: 2026 | D40: 537993.83 | N40: 2026
X41: Of which, through "indexation measures":
W42: 2023 | X42: =(($M37-$H37)/1000000)/T37 -> 0.40964165 | Y42: =(($M37-$H37)/1000000)/U37 -> 0.42547157 | Z42: =(($M37-$H37)/1000000)/V37 -> 0.29619431 | AA42: =AVERAGE(X42:Z42) -> 0.37710251
B44: Table for Figure (million euros) | D44: For reescaling | F44: All these are reescaled | U44: Table for Figure (share GDP) | W44: For reescaling | Y44: All these are reescaled
C45: Baseline simulation (before reescaling) | D45: Observed (National Accounts) | E45: Reescaling factor | F45: Baseline simulation (after reescaling) | G45: Unchanged legislation since 2019/2023 | H45: Indexing with tax base growth | I45: Indexing with lagged HCPI | J45: Indexing with concurrent HCPI | K45: Baseline w/o "indexation measures" | V45: Baseline simulation (before reescaling) | W45: Observed (National Accounts) | X45: Reescaling factor | Y45: Baseline simulation (after reescaling) | Z45: Unchanged legislation since 2019/2023 | AA45: Indexing with tax base growth | AB45: Indexing with lagged HCPI | AC45: Indexing with concurrent HCPI
B46: 2019 | C46: =C33/1000000 -> 35100.628 | D46: =F33/1000000 -> 35423.871 | F46: =H33/1000000 -> 35423.871 | U46: 2019 | V46: =C33/1000000/D33 -> 0.088703634 | W46: =F33/(D33*1000000) -> 0.089520508 | Y46: =H33/($D33*1000000) -> 0.089520508
...

Sheet 1BE
B2: Template corresponding to Part 1 of the project Fiscal Drag in Europe
B3: Yellow cells have to be filled by you (remember to rename the sheets as well)
B4: Remaing cells are automatically calculated using information from yellow cells (grey cells remain empty)
B8: Country | C8: BE | D8: Belgium | E8: Updated:10/02/2025 (indepth) [ 24/09/2024 (data) (fileversion 22/10/2024)]
C10: Personal Income Tax Revenue | P10: Tac Base (il_fiscaldrag_all) | W10: TTB | AD10: TTB by income source | AH10: Decomposition of TTB in pp | AQ10: Decomposition of fiscal drag in percentage | AZ10: OECD estimates | CC10: Ratio8020 all income | CK10: Gini tax base (from Table 3.1) | CS10: Ratio8020 tax base | DA10: Kakwani (from Table 3.2) | DD10: Share taxpayers | EA10: 2023 Personal Income Tax Revenue | EN10: 2023 Tax Base (il_fiscaldrag_all) | EV10: 2023 TTB | EZ10: 2023 Share taxpayers | FB10: 2023 TTB by income source
